## 4. 错误处理模式

### 统一错误处理

```typescript
// src/types/error.types.ts
export interface AppError {
  code: string;
  message: string;
  details?: Record<string, any>;
  timestamp: number;
}

export class CustomError extends Error {
  constructor(
    public code: string,
    message: string,
    public details?: Record<string, any>
  ) {
    super(message);
    this.name = 'CustomError';
  }
}

// src/utils/error.utils.ts
export function createError(code: string, message: string, details?: Record<string, any>): CustomError {
  return new CustomError(code, message, details);
}

export function isCustomError(error: unknown): error is CustomError {
  return error instanceof CustomError;
}

export function handleError(error: unknown): AppError {
  if (isCustomError(error)) {
    return {
      code: error.code,
      message: error.message,
      details: error.details,
      timestamp: Date.now()
    };
  }
  
  return {
    code: 'UNKNOWN_ERROR',
    message: error instanceof Error ? error.message : 'An unknown error occurred',
    timestamp: Date.now()
  };
}

// src/services/api.service.ts
import { AppError, handleError, createError } from '../utils/error.utils';

export class ApiService {
  static async request<T>(url: string, options?: RequestInit): Promise<T> {
    try {
      const response = await fetch(url, options);
      
      if (!response.ok) {
        throw createError(
          `HTTP_${response.status}`,
          `HTTP Error: ${response.status} ${response.statusText}`,
          { status: response.status, url }
        );
      }
      
      return await response.json();
    } catch (error) {
      const appError = handleError(error);
      console.error('API Error:', appError);
      throw appError;
    }
  }
}
```

### 异步操作错误处理

```typescript
// src/utils/async.utils.ts
export type Result<T, E = AppError> = {
  success: true;
  data: T;
} | {
  success: false;
  error: E;
};

export async function safeExecute<T>(
  asyncFn: () => Promise<T>
): Promise<Result<T>> {
  try {
    const data = await asyncFn();
    return { success: true, data };
  } catch (error) {
    return { success: false, error: handleError(error) };
  }
}

// 使用示例
async function fetchUserData(userId: number) {
  const result = await safeExecute(() => 
    ApiService.request<User>(`/api/users/${userId}`)
  );
  
  if (result.success) {
    return result.data;
  } else {
    console.error('Failed to fetch user:', result.error);
    return null;
  }
}
```

### 验证和断言

```typescript
// src/utils/validation.utils.ts
export function assert(condition: unknown, message: string): asserts condition {
  if (!condition) {
    throw new Error(message);
  }
}

export function assertNotNull<T>(value: T | null | undefined, message: string): T {
  assert(value != null, message);
  return value;
}

export function validateEmail(email: string): boolean {
  const emailRegex = /^[^\s@]+@[^\s@]+\.[^\s@]+$/;
  return emailRegex.test(email);
}

// 使用示例
function processUser(user: User | null) {
  // 使用断言确保值存在
  assertNotNull(user, 'User cannot be null');
  
  // 现在 TypeScript 知道 user 不为 null
  console.log(user.name);
  
  // 验证邮箱
  if (!validateEmail(user.email)) {
    throw createError('INVALID_EMAIL', 'Invalid email format');
  }
}
```