## **错误处理**

在 JavaScript 中，错误处理是确保程序健壮性和稳定性的重要部分。通过错误处理机制，可以捕获运行时的异常并采取适当的措施，避免程序崩溃或产生不可预测的行为。以下是关于 `try...catch...finally` 和自定义错误的详细讲解。

---

### **1.`try...catch...finally`**

`try...catch...finally` 是 JavaScript 中用于捕获和处理异常的核心结构。它允许开发者在代码块中捕获错误，并执行相应的错误处理逻辑。

#### **基本语法**

```javascript
try {
    // 可能抛出错误的代码
} catch (error) {
    // 捕获并处理错误
} finally {
    // 无论是否发生错误都会执行的代码
}
```

- **`try`**：包含可能抛出错误的代码。
- **`catch`**：捕获由 `try` 块抛出的错误，并提供错误对象（通常命名为 `error`）。
- **`finally`**：无论是否发生错误，都会执行的代码块，通常用于清理资源（如关闭文件、释放内存等）。

#### **示例**

```javascript
try {
    const result = riskyOperation();
    console.log(result);
} catch (error) {
    console.error("An error occurred:", error.message);
} finally {
    console.log("Execution completed.");
}

function riskyOperation() {
    throw new Error("Something went wrong!");
}
// 输出：
// An error occurred: Something went wrong!
// Execution completed.
```

#### **详细说明**

1. **`try` 块**：
   - 包含需要监控的代码。
   - 如果 `try` 块中的代码抛出错误，程序会立即跳转到 `catch` 块。

2. **`catch` 块**：
   - 接收一个参数（通常是 `error` 对象），包含错误信息。
   - 错误对象通常包括以下属性：
     - `message`：错误的描述信息。
     - `name`：错误的类型（如 `Error`、`TypeError` 等）。
     - `stack`：错误的调用栈信息（用于调试）。
   - 示例：

     ```javascript
     try {
         null.property; // 引发 TypeError
     } catch (error) {
         console.log(error.name); // 输出：TypeError
         console.log(error.message); // 输出：Cannot read properties of null
         console.log(error.stack); // 输出：完整的调用栈信息
     }
     ```

3. **`finally` 块**：
   - 无论 `try` 块是否抛出错误，`finally` 块都会执行。
   - 适用于清理操作，例如关闭数据库连接、释放锁等。
   - 示例：

     ```javascript
     try {
         console.log("Try block executed.");
         throw new Error("Test error");
     } catch (error) {
         console.log("Catch block executed.");
     } finally {
         console.log("Finally block executed.");
     }
     // 输出：
     // Try block executed.
     // Catch block executed.
     // Finally block executed.
     ```

#### **注意事项**

1. **嵌套 `try...catch`**：
   - 可以在一个 `try` 块中嵌套另一个 `try...catch`，以便更精细地控制错误处理。

     ```javascript
     try {
         try {
             throw new Error("Inner error");
         } catch (innerError) {
             console.log("Inner catch:", innerError.message);
             throw innerError; // 重新抛出错误
         }
     } catch (outerError) {
         console.log("Outer catch:", outerError.message);
     }
     // 输出：
     // Inner catch: Inner error
     // Outer catch: Inner error
     ```

2. **未捕获的错误**：
   - 如果错误未被捕获，程序会崩溃并输出错误信息。
   - 在浏览器环境中，可以通过 `window.onerror` 全局捕获未处理的错误。

     ```javascript
     window.onerror = function(message, source, lineno, colno, error) {
         console.log("Global error handler:", message);
         return true; // 阻止默认行为
     };

     throw new Error("Uncaught error");
     // 输出：Global error handler: Uncaught error
     ```

---

### **2. 自定义错误：`throw new Error('message')`**

JavaScript 提供了内置的 `Error` 类，用于创建标准错误对象。开发者还可以通过 `throw` 关键字手动抛出自定义错误。

#### **抛出错误**

使用 `throw` 关键字可以显式地抛出一个错误对象或其他类型的值。

**语法**：

```javascript
throw 表达式;
```

- 表达式可以是任何值，但通常是一个 `Error` 对象。

**示例**：

```javascript
function divide(a, b) {
    if (b === 0) {
        throw new Error("Division by zero is not allowed.");
    }
    return a / b;
}

try {
    console.log(divide(10, 0));
} catch (error) {
    console.error("Error:", error.message);
}
// 输出：
// Error: Division by zero is not allowed.
```

#### **自定义错误类**

除了使用内置的 `Error` 类，还可以通过继承 `Error` 创建自定义错误类，以满足特定需求。

**示例**：

```javascript
class ValidationError extends Error {
    constructor(message) {
        super(message); // 调用父类构造函数
        this.name = "ValidationError"; // 设置错误名称
    }
}

function validateInput(input) {
    if (!input) {
        throw new ValidationError("Input cannot be empty.");
    }
    console.log("Input is valid.");
}

try {
    validateInput("");
} catch (error) {
    if (error instanceof ValidationError) {
        console.error("Validation error:", error.message);
    } else {
        console.error("Unexpected error:", error.message);
    }
}
// 输出：
// Validation error: Input cannot be empty.
```

#### **常见内置错误类型**

JavaScript 提供了一些内置的错误类型，用于表示不同类型的错误：

1. **`Error`**：通用错误基类。
2. **`SyntaxError`**：语法错误。
3. **`ReferenceError`**：引用不存在的变量。
4. **`TypeError`**：操作不符合数据类型。
5. **`RangeError`**：数值超出有效范围。
6. **`URIError`**：URI 编码/解码错误。

**示例**：

```javascript
try {
    JSON.parse("{"); // 不完整的 JSON 字符串
} catch (error) {
    if (error instanceof SyntaxError) {
        console.error("Syntax error:", error.message);
    }
}
// 输出：
// Syntax error: Unexpected end of JSON input
```

#### **动态生成错误**

可以根据条件动态生成错误信息，增强错误描述的清晰度。

**示例**：

```javascript
function calculateDiscount(price, discount) {
    if (discount < 0 || discount > 100) {
        throw new RangeError(`Invalid discount value: ${discount}. Must be between 0 and 100.`);
    }
    return price * (1 - discount / 100);
}

try {
    console.log(calculateDiscount(100, 150));
} catch (error) {
    console.error("Error:", error.message);
}
// 输出：
// Error: Invalid discount value: 150. Must be between 0 and 100.
```

---