## **1. 异常机制**

### **1.1 `try`, `catch`, `throw`**

C++ 的异常处理机制基于三个关键字：`try`, `catch`, 和 `throw`。

- **`try` 块**：
  - 用于包裹可能抛出异常的代码。
  - 如果在 `try` 块中发生异常，程序会跳转到匹配的 `catch` 块进行处理。

- **`throw` 表达式**：
  - 用于抛出异常，可以抛出任何类型的值（通常是对象）。
  - 抛出异常后，程序会立即跳出当前函数，并寻找最近的匹配 `catch` 块。

- **`catch` 块**：
  - 用于捕获和处理特定类型的异常。
  - 可以有多个 `catch` 块，分别处理不同类型的异常。

**语法**：

```cpp
try {
    // 可能抛出异常的代码
} catch (异常类型1 参数) {
    // 处理异常类型1
} catch (异常类型2 参数) {
    // 处理异常类型2
} catch (...) { // 捕获所有异常
    // 处理未知异常
}
```

**示例**：
以下是一个简单的异常处理示例：

```cpp
#include <iostream>
using namespace std;

void divide(int a, int b) {
    if (b == 0) {
        throw runtime_error("Division by zero"); // 抛出异常
    }
    cout << "Result: " << a / b << endl;
}

int main() {
    try {
        divide(10, 0); // 尝试除以零
    } catch (const exception& e) { // 捕获标准异常
        cout << "Error: " << e.what() << endl; // 输出错误信息
    }
    return 0;
}
```

### **1.2 自定义异常类**

除了使用标准异常类（如 `std::runtime_error`），我们还可以定义自己的异常类来表示特定的错误。

**示例**：
以下是一个自定义异常类的示例：

```cpp
#include <iostream>
#include <string>
using namespace std;

// 定义自定义异常类
class MyException : public exception {
private:
    string message;
public:
    MyException(const string& msg) : message(msg) {}
    const char* what() const noexcept override {
        return message.c_str();
    }
};

void checkAge(int age) {
    if (age < 18) {
        throw MyException("Age must be at least 18");
    }
    cout << "Age is valid" << endl;
}

int main() {
    try {
        checkAge(16); // 尝试传递无效年龄
    } catch (const exception& e) {
        cout << "Error: " << e.what() << endl; // 输出自定义错误信息
    }
    return 0;
}
```

---